[2025-06-03 03:33:32,793] ERROR [push_data.py:92] - Exception occurred while inserting into MongoDB
Traceback (most recent call last):
  File "D:\Projects\NETWORKSECURITY\push_data.py", line 88, in insert_data_to_mongodb
    self.collection.insert_many(self.records)
  File "D:\Projects\NETWORKSECURITY\venv\Lib\site-packages\pymongo\_csot.py", line 119, in csot_wrapper
    return func(self, *args, **kwargs)
           ^^^^^^^^^^^^^^^^^^^^^^^^^^^
  File "D:\Projects\NETWORKSECURITY\venv\Lib\site-packages\pymongo\synchronous\collection.py", line 975, in insert_many
    blk.execute(write_concern, session, _Op.INSERT)
  File "D:\Projects\NETWORKSECURITY\venv\Lib\site-packages\pymongo\synchronous\bulk.py", line 751, in execute
    return self.execute_command(generator, write_concern, session, operation)
           ^^^^^^^^^^^^^^^^^^^^^^^^^^^^^^^^^^^^^^^^^^^^^^^^^^^^^^^^^^^^^^^^^^
  File "D:\Projects\NETWORKSECURITY\venv\Lib\site-packages\pymongo\synchronous\bulk.py", line 604, in execute_command
    _ = client._retryable_write(
        ^^^^^^^^^^^^^^^^^^^^^^^^
  File "D:\Projects\NETWORKSECURITY\venv\Lib\site-packages\pymongo\synchronous\mongo_client.py", line 2061, in _retryable_write
    return self._retry_with_session(retryable, func, s, bulk, operation, operation_id)
           ^^^^^^^^^^^^^^^^^^^^^^^^^^^^^^^^^^^^^^^^^^^^^^^^^^^^^^^^^^^^^^^^^^^^^^^^^^^
  File "D:\Projects\NETWORKSECURITY\venv\Lib\site-packages\pymongo\synchronous\mongo_client.py", line 1947, in _retry_with_session
    return self._retry_internal(
           ^^^^^^^^^^^^^^^^^^^^^
  File "D:\Projects\NETWORKSECURITY\venv\Lib\site-packages\pymongo\_csot.py", line 119, in csot_wrapper
    return func(self, *args, **kwargs)
           ^^^^^^^^^^^^^^^^^^^^^^^^^^^
  File "D:\Projects\NETWORKSECURITY\venv\Lib\site-packages\pymongo\synchronous\mongo_client.py", line 1993, in _retry_internal
    ).run()
      ^^^^^
  File "D:\Projects\NETWORKSECURITY\venv\Lib\site-packages\pymongo\synchronous\mongo_client.py", line 2730, in run
    return self._read() if self._is_read else self._write()
                                              ^^^^^^^^^^^^^
  File "D:\Projects\NETWORKSECURITY\venv\Lib\site-packages\pymongo\synchronous\mongo_client.py", line 2840, in _write
    self._server = self._get_server()
                   ^^^^^^^^^^^^^^^^^^
  File "D:\Projects\NETWORKSECURITY\venv\Lib\site-packages\pymongo\synchronous\mongo_client.py", line 2823, in _get_server
    return self._client._select_server(
           ^^^^^^^^^^^^^^^^^^^^^^^^^^^^
  File "D:\Projects\NETWORKSECURITY\venv\Lib\site-packages\pymongo\synchronous\mongo_client.py", line 1812, in _select_server
    server = topology.select_server(
             ^^^^^^^^^^^^^^^^^^^^^^^
  File "D:\Projects\NETWORKSECURITY\venv\Lib\site-packages\pymongo\synchronous\topology.py", line 409, in select_server
    server = self._select_server(
             ^^^^^^^^^^^^^^^^^^^^
  File "D:\Projects\NETWORKSECURITY\venv\Lib\site-packages\pymongo\synchronous\topology.py", line 387, in _select_server
    servers = self.select_servers(
              ^^^^^^^^^^^^^^^^^^^^
  File "D:\Projects\NETWORKSECURITY\venv\Lib\site-packages\pymongo\synchronous\topology.py", line 294, in select_servers
    server_descriptions = self._select_servers_loop(
                          ^^^^^^^^^^^^^^^^^^^^^^^^^^
  File "D:\Projects\NETWORKSECURITY\venv\Lib\site-packages\pymongo\synchronous\topology.py", line 344, in _select_servers_loop
    raise ServerSelectionTimeoutError(
pymongo.errors.ServerSelectionTimeoutError: SSL handshake failed: ac-d1v4l9p-shard-00-00.l0fwss3.mongodb.net:27017: [SSL: TLSV1_ALERT_INTERNAL_ERROR] tlsv1 alert internal error (_ssl.c:992) (configured timeouts: socketTimeoutMS: 20000.0ms, connectTimeoutMS: 20000.0ms),SSL handshake failed: ac-d1v4l9p-shard-00-02.l0fwss3.mongodb.net:27017: [SSL: TLSV1_ALERT_INTERNAL_ERROR] tlsv1 alert internal error (_ssl.c:992) (configured timeouts: socketTimeoutMS: 20000.0ms, connectTimeoutMS: 20000.0ms),SSL handshake failed: ac-d1v4l9p-shard-00-01.l0fwss3.mongodb.net:27017: [SSL: TLSV1_ALERT_INTERNAL_ERROR] tlsv1 alert internal error (_ssl.c:992) (configured timeouts: socketTimeoutMS: 20000.0ms, connectTimeoutMS: 20000.0ms), Timeout: 30s, Topology Description: <TopologyDescription id: 683ecf4356b8b19865da0549, topology_type: ReplicaSetNoPrimary, servers: [<ServerDescription ('ac-d1v4l9p-shard-00-00.l0fwss3.mongodb.net', 27017) server_type: Unknown, rtt: None, error=AutoReconnect('SSL handshake failed: ac-d1v4l9p-shard-00-00.l0fwss3.mongodb.net:27017: [SSL: TLSV1_ALERT_INTERNAL_ERROR] tlsv1 alert internal error (_ssl.c:992) (configured timeouts: socketTimeoutMS: 20000.0ms, connectTimeoutMS: 20000.0ms)')>, <ServerDescription ('ac-d1v4l9p-shard-00-01.l0fwss3.mongodb.net', 27017) server_type: Unknown, rtt: None, error=AutoReconnect('SSL handshake failed: ac-d1v4l9p-shard-00-01.l0fwss3.mongodb.net:27017: [SSL: TLSV1_ALERT_INTERNAL_ERROR] tlsv1 alert internal error (_ssl.c:992) (configured timeouts: socketTimeoutMS: 20000.0ms, connectTimeoutMS: 20000.0ms)')>, <ServerDescription ('ac-d1v4l9p-shard-00-02.l0fwss3.mongodb.net', 27017) server_type: Unknown, rtt: None, error=AutoReconnect('SSL handshake failed: ac-d1v4l9p-shard-00-02.l0fwss3.mongodb.net:27017: [SSL: TLSV1_ALERT_INTERNAL_ERROR] tlsv1 alert internal error (_ssl.c:992) (configured timeouts: socketTimeoutMS: 20000.0ms, connectTimeoutMS: 20000.0ms)')>]>
